Workbook

Sheet Sheet2
A3: Count of Customer Number
A4: H.O. Code | B4: Total
A5: 1000089 | B5: 8 | C5: =VLOOKUP(A5,'[1]AR vs Collections 31.05.2025'!$B$566:$C$585,2,0) -> SHETA AL SAIF
A6: 1000013 | B6: 7 | C6: =VLOOKUP(A6,'[1]AR vs Collections 31.05.2025'!$B$566:$C$585,2,0) -> LULU
A7: 1000001 | B7: 7 | C7: C4
A8: 1000057 | B8: 6 | C8: =VLOOKUP(A8,'[1]AR vs Collections 31.05.2025'!$B$566:$C$585,2,0) -> AFAQ Q Tech General Trading LLC-Amazon
A9: 3000105 | B9: 6 | C9: =VLOOKUP(A9,'[1]AR vs Collections 31.05.2025'!$B$566:$C$585,2,0) -> EXTRA
A10: 2000633 | B10: 6 | C10: =VLOOKUP(A10,'[1]AR vs Collections 31.05.2025'!$B$566:$C$585,2,0) -> Bin Hamoud Saudi Trading Company
A11: 3000432 | B11: 5 | C11: Ajwa Al Yamamah
A12: 3000079 | B12: 5 | C12: Muhammad Jawad Saleh Muhammad
A13: 2000546 | B13: 5 | C13: Dharkam
A14: 3000433 | B14: 4 | C14: =VLOOKUP(A14,'[1]AR vs Collections 31.05.2025'!$B$566:$C$585,2,0) -> Mohamed Saleh Aldossary Co. Ltd
A15: 2000650 | B15: 4 | C15: Mohammed Hassan Omar Al Amoudi Trad
A16: 2000611 | B16: 4 | C16: Artal Arabia Limited Company
A17: 2000518 | B17: 4 | C17: Fakhamat Air Conditioning Est.
A18: 1000797 | B18: 4 | C18: Yousef Abdul Karim Mohammed
A19: 3000493 | B19: 4 | C19: شركة وهج الاصيل للمقاولات شركة شخص واحد
A20: 1000905 | B20: 4 | C20: Bandar Ali AlSudairi Trading Est
A21: 3000444 | B21: 4 | C21: =VLOOKUP(A21,Sheet4!A:B,2,0) -> Cold World Trading Est
A22: 1000480 | B22: 4 | C22: =VLOOKUP(A22,Sheet4!A:B,2,0) -> Black Box Co.
A23: 2000558 | B23: 4 | C23: =VLOOKUP(A23,Sheet4!A:B,2,0) -> Al Masa Mall Company for
A24: 1000639 | B24: 4 | C24: =VLOOKUP(A24,'[1]AR vs Collections 31.05.2025'!$B$566:$C$585,2,0) -> Noon Solution E-Commerce co
A25: 2000564 | B25: 4 | C25: =VLOOKUP(A25,Sheet4!A:B,2,0) -> Muhammad Fayez Ali Al Shehri Tradin
A26: 1000877 | B26: 4 | C26: =VLOOKUP(A26,Sheet4!A:B,2,0) -> Mumzworld Arabia Co for Business se
A27: 1000471 | B27: 4 | C27: =VLOOKUP(A27,'[1]AR vs Collections 31.05.2025'!$B$566:$C$585,2,0) -> AlManea Co, Ltd
A28: 3000439 | B28: 4 | C28: =VLOOKUP(A28,Sheet4!A:B,2,0) -> Al Othman Trading Limited Liability
A29: 2000576 | B29: 4 | C29: =VLOOKUP(A29,Sheet4!A:B,2,0) -> Diyar Al Fares Trading Company
A30: 2000594 | B30: 4 | C30: =VLOOKUP(A30,Sheet4!A:B,2,0) -> Khudair Abdul Rahman Muhammad
A31: 2000531 | B31: 4 | C31: =VLOOKUP(A31,Sheet4!A:B,2,0) -> United Vision Trading Company
A32: 1000795 | B32: 3 | C32: =VLOOKUP(A32,Sheet4!A:B,2,0) -> Al Rabee & Al Saif Trading Company
A33: 3000501 | B33: 3 | C33: =VLOOKUP(A33,Sheet4!A:B,2,0) -> Fahad Al Shamal Establishment for H
A34: 2000525 | B34: 3 | C34: =VLOOKUP(A34,Sheet4!A:B,2,0) -> Muhammad Misfer Hussein Al Musleh
A35: 1000888 | B35: 3 | C35: =VLOOKUP(A35,Sheet4!A:B,2,0) -> Silver Dome Trading Est
A36: 2000688 | B36: 3 | C36: =VLOOKUP(A36,Sheet4!A:B,2,0) -> Al Safwa Plus Electronic Devices Co
A37: 1000904 | B37: 3 | C37: =VLOOKUP(A37,Sheet4!A:B,2,0) -> Basil bin Fahd bin Miteb Al Mazyad
A38: 3000431 | B38: 3 | C38: =VLOOKUP(A38,Sheet4!A:B,2,0) -> Mirza Redha Al-Jashi General
A39: 1000793 | B39: 3 | C39: =VLOOKUP(A39,Sheet4!A:B,2,0) -> Al Rowad Electronics Company
A40: 3000438 | B40: 3 | C40: Saleh & Abdul Wahab Al Mousa
A41: 1000920 | B41: 3 | C41: =VLOOKUP(A41,Sheet4!A:B,2,0) -> Qasr Al Awani Company closed Saudi
A42: 1000079 | B42: 3 | C42: =VLOOKUP(A42,Sheet4!A:B,2,0) -> Carrefour Saudi Hypermarkets Co
...

Sheet Sheet3
A3: Count of Customer Name
A4: H.O. Code | B4: Customer Name | C4: Total
A5: 1000001 | B5: C4 Flamingo Mall - Jeddah III | C5: 1
A6: 1000001 | B6: C4 Sulamaniya Mall | C6: 1
A7: 1000001 | B7: C4 Madinah | C7: 1
A8: 1000001 | B8: C4 Granada | C8: 1
A9: 1000001 | B9: C4 WEST AVENUE MALL - DAMMAM | C9: 1
A10: 1000001 | B10: C4 Khurais | C10: 1
A11: 1000001 | B11: C4 Leemall | C11: 1
A12: 1000013 | B12: LuLu Jeddah -Gaming | C12: 1
A13: 1000013 | B13: Lulu Saudi Hypermarkets LLC – ESD | C13: 1
A14: 1000013 | B14: LuLu Central WH -Riyadh (CAV) | C14: 1
A15: 1000013 | B15: LuLu Khobar -Gaming | C15: 1
A16: 1000013 | B16: Saudi LULU Co. for Hypermarkets | C16: 1
... A307: 1400006100 | B307: Electronics & Systems Holding Company | C307: 1
A308: DAMAM | B308: Dammam Showroom | C308: 1
A309: DAMAM2 | B309: Dammam 2 Showroom | C309: 1
A310: DS01 | B310: La3eb | C310: 1
A311: GRNAD | B311: Granada Mall Showroom | C311: 1
A312: HASSA | B312: Hassa Showroom | C312: 1
A313: JS02 | B313: MECL-JED Tabuk Showroom | C313: 1
A314: JS07 | B314: MECL-JED-Khamis Mushayat Showroom | C314: 1
A315: JS15 | B315: MECL-JED-La Terra Mall Sh | C315: 1
A316: KFAHD | B316: King Fahd Showroom | C316: 1
A317: KS01 | B317: MECL-KHB-King Fahd Showroom | C317: 1
A318: KS03 | B318: MECL-KHB-Dammam Showroom | C318: 1
A319: KS04 | B319: MECL-KHB-Al Hassa Showroo | C319: 1
... A336: WAROOD | B336: MECL-RYD-Warood Showroom | C336: 1
A337: Grand Total | C337: 464

Sheet Sheet4
A1: H.O. Code | B1: Customer Name | C1: Total
A2: 1000057 | B2: AFAQ Q Tech General Trading LLC | C2: 5
A3: 1000079 | B3: Carrefour Saudi Hypermarkets Co | C3: 3
A4: 1000089 | B4: Sheta & Al Saif Trading Company | C4: 5
A5: 1000471 | B5: Hamad Bin Abdullah Bin Sulaiman Almanea | C5: 2
A6: 1000471 | B6: Hamad Abdullah Bin Suleman Almanea | C6: 2
A7: 1000480 | B7: Black Box Co. | C7: 2
A8: 1000639 | B8: Noon E Commerce Solutions | C8: 3
A9: 1000793 | B9: Al Rowad Electronics Company | C9: 3
A10: 1000795 | B10: Al Rabee & Al Saif Trading Company | C10: 2
A11: 1000797 | B11: Yousef Abdul Karim Mohammed | C11: 3
A12: 1000798 | B12: Hussain Fahad Metaab AlMaziad | C12: 2
A13: 1000830 | B13: Alinthalaq Trading Establishment | C13: 2
... A87: 3000509 | B87: Al Roya Al Barda for Refrigeration | C87: 3
A88: Grand Total | C88: 464

Sheet Sheet1
A1: Customer Number | B1: Customer Name | C1: H.O. Code | D1: H.O Name
A2: 3000493 | B2: شركة وهج الاصيل للمقاولات شركة شخص واحد | C2: 3000493 | D2: =VLOOKUP(C2,Sheet2!A:C,3,0) -> شركة وهج الاصيل للمقاولات شركة شخص واحد
A3: 3000494 | B3: شركة وهج الاصيل للمقاولات شركة شخص واحد | C3: 3000493 | D3: =VLOOKUP(C3,Sheet2!A:C,3,0) -> شركة وهج الاصيل للمقاولات شركة شخص واحد
A4: 3000495 | B4: شركة وهج الاصيل للمقاولات شركة شخص واحد | C4: 3000493 | D4: =VLOOKUP(C4,Sheet2!A:C,3,0) -> شركة وهج الاصيل للمقاولات شركة شخص واحد
A5: 3000496 | B5: شركة وهج الاصيل للمقاولات شركة شخص واحد | C5: 3000496 | D5: =VLOOKUP(C5,Sheet2!A:C,3,0) -> شركة وهج الاصيل للمقاولات شركة شخص واحد
A6: 3000507 | B6: شركة وهج الاصيل للمقاولات شركة شخص واحد | C6: 3000493 | D6: =VLOOKUP(C6,Sheet2!A:C,3,0) -> شركة وهج الاصيل للمقاولات شركة شخص واحد
A7: 1000796 | B7: شركة هواوي تك. انفستمنت العربية | C7: + | D7: =VLOOKUP(C7,Sheet2!A:C,3,0) -> #N/A
A8: 1000565 | B8: Zill Najd Trading Co. | C8: 1000565 | D8: =VLOOKUP(C8,Sheet2!A:C,3,0) -> Zill Najd Trading Co.
A9: 1000979 | B9: Zension Saudi Information | C9: 1000979 | D9: =VLOOKUP(C9,Sheet2!A:C,3,0) -> Zension Saudi Information
A10: 2000422 | B10: Zelal al jasmin Trading | C10: 2000422 | D10: =VLOOKUP(C10,Sheet2!A:C,3,0) -> Zelal al jasmin Trading
A11: 1000790 | B11: Zed Game Trading Company | C11: 1000790 | D11: =VLOOKUP(C11,Sheet2!A:C,3,0) -> Zed Game Trading Company
A12: 2000113 | B12: Zaid First Trading Company | C12: 2000113 | D12: =VLOOKUP(C12,Sheet2!A:C,3,0) -> Zaid First Trading Company
A13: 2000738 | B13: Zagzoog For Home Appliances Co LTD | C13: 2000738 | D13: =VLOOKUP(C13,Sheet2!A:C,3,0) -> Zagzoog For Home Appliances Co LTD
A14: 3000434 | B14: Youssef Abdel Wahab Al Mousa | C14: 3000434 | D14: =VLOOKUP(C14,Sheet2!A:C,3,0) -> Youssef Abdel Wahab Al Mousa
A15: 1000797 | B15: Yousef Abdul Karim Mohammed | C15: 1000797 | D15: =VLOOKUP(C15,Sheet2!A:C,3,0) -> Yousef Abdul Karim Mohammed
A16: 1000859 | B16: Yousef Abdul Karim Mohammed | C16: 1000797 | D16: =VLOOKUP(C16,Sheet2!A:C,3,0) -> Yousef Abdul Karim Mohammed
A17: 1000885 | B17: Yousef Abdul Karim Mohammed | C17: 1000797 | D17: =VLOOKUP(C17,Sheet2!A:C,3,0) -> Yousef Abdul Karim Mohammed
A18: 1001014 | B18: مؤسسة يوسف عبد الكريم محمد الحركان التج | C18: 1000797 | D18: =VLOOKUP(C18,Sheet2!A:C,3,0) -> Yousef Abdul Karim Mohammed
A19: 1000764 | B19: YouGotaGift | C19: 1000764 | D19: =VLOOKUP(C19,Sheet2!A:C,3,0) -> YouGotaGift
... A51: 2000625 | B51: Tafaroud AlRoyah Co for Investment | C51: 2000514 | D51: =VLOOKUP(C51,Sheet2!A:C,3,0) -> Tafaroud Alroyah Co. for Investment
A52: TABUK | B52: Tabuk Showroom | C52: TABUK | D52: =VLOOKUP(C52,Sheet2!A:C,3,0) -> Tabuk Showroom
A53: 2000534 | B53: Summer Breeze Trading Company | C53: 2000534 | D53: =VLOOKUP(C53,Sheet2!A:C,3,0) -> Summer Breeze Trading Company
A54: 2000006 | B54: Sultan Bawahab_Binzagar St | C54: 2000006 | D54: =VLOOKUP(C54,Sheet2!A:C,3,0) -> Sultan Bawahab_Binzagar St
A55: 1000819 | B55: Sroor Obaid Alhamazani | C55: 1000819 | D55: =VLOOKUP(C55,Sheet2!A:C,3,0) -> Sroor Obaid Alhamazani
A56: OC01 | B56: SONYWORLD.SA | C56: OC01 | D56: =VLOOKUP(C56,Sheet2!A:C,3,0) -> SONYWORLD.SA
A57: RS17 | B57: Sony Showroom Warood | C57: RS17 | D57: =VLOOKUP(C57,Sheet2!A:C,3,0) -> Sony Showroom Warood
A58: 7000001 | B58: Sony Middle East And Africa | C58: 7000001 | D58: =VLOOKUP(C58,Sheet2!A:C,3,0) -> Sony Middle East And Africa
A59: 7000004 | B59: Sony Interactive Entertainment Europe | C59: 7000004 | D59: =VLOOKUP(C59,Sheet2!A:C,3,0) -> Sony Interactive Entertainment Europe
A60: 2000602 | B60: Somaya Mohammed Al-Ghamdi | C60: 2000602 | D60: =VLOOKUP(C60,Sheet2!A:C,3,0) -> Somaya Mohammed Al-Ghamdi
A61: 1001027 | B61: Smart Sources Company | C61: 1001027 | D61: =VLOOKUP(C61,Sheet2!A:C,3,0) -> Smart Sources Company
A62: 2000587 | B62: Smart Air Conditioning Corner | C62: 2000587 | D62: =VLOOKUP(C62,Sheet2!A:C,3,0) -> Smart Air Conditioning Corner
A63: 1000888 | B63: Silver Dome Trading Est | C63: 1000888 | D63: =VLOOKUP(C63,Sheet2!A:C,3,0) -> Silver Dome Trading Est
A64: 1001028 | B64: Silver Dome Trading Est | C64: 1000888 | D64: =VLOOKUP(C64,Sheet2!A:C,3,0) -> Silver Dome Trading Est
A65: 1001029 | B65: Silver Dome Trading Est | C65: 1000888 | D65: =VLOOKUP(C65,Sheet2!A:C,3,0) -> Silver Dome Trading Est
A66: 1000089 | B66: Sheta & Al Saif Trading Company | C66: 1000089 | D66: =VLOOKUP(C66,Sheet2!A:C,3,0) -> SHETA AL SAIF
A67: 1000598 | B67: Sheta & Al Saif Trading Company | C67: 1000089 | D67: =VLOOKUP(C67,Sheet2!A:C,3,0) -> SHETA AL SAIF
A68: 1000794 | B68: Sheta & Al Saif Trading Company | C68: 1000089 | D68: =VLOOKUP(C68,Sheet2!A:C,3,0) -> SHETA AL SAIF
A69: 1000801 | B69: Sheta & Al Saif Trading Company | C69: 1000089 | D69: =VLOOKUP(C69,Sheet2!A:C,3,0) -> SHETA AL SAIF
... A172: 3000478 | B172: Mirza Redha Al Jishi General Contra | C172: 3000431 | D172: =VLOOKUP(C172,Sheet2!A:C,3,0) -> Mirza Redha Al-Jashi General
A173: MESTORES | B173: Mestores.com | C173: MESTORES | D173: =VLOOKUP(C173,Sheet2!A:C,3,0) -> Mestores.com
...
